Workbook
Name building_layer: [1]Dropdowns!$D$5:$D$7
Name Densities: [1]Densities!$A$4:$E$410
Name dimension_calc: [1]Dropdowns!$T$5:$T$8
Name Level1_matcat: [1]Material_classif_dropdowns!$B$5:$B$14
Name Material_categories: '[1]Crossmatch material classific.'!$A$1:$Z$491

Sheet Progress Notes
A1: Date | B1: Sheet | C1: Note | D1: Status | H1: Reference (Så byggdes husen 1880 - 2020) | I1: Archetype | J1: ROOF | K1: TOP_FLOOR | L1: INTERMEDIATE_FLOOR | M1: GROUND_FLOOR | N1: BASEMENT_FLOOR | O1: EXT_WALL_LOW | P1: EXT_WALL_MEDIUM | Q1: EXT_WALL_HIGH | R1: BASEMENT_WALL | S1: INT_WALL_LOADBEARING | T1: INT_WALL_NONLOADBEARING | U1: EXT_WALL
A2: Date of change/comment. | B2: The sheet that changes/comments concern | C2: Short description of content | D2: Completed/Pending | H2: Page 80 - 81 | I2: CMF_1940_1 | J2: x | K2: x | L2: x | M2: x | N2: x | R2: x | S2: x | T2: x | U2: x
A3: 45989 | B3: Opaque_Materials & Window_Materials | C3: Complete adding the materials for the two archetypes | D3: Completed | H3: Page 94 - 95 | I3: CMF_1950 | J3: x | K3: x | L3: x | M3: x | N3: x | O3: x | P3: x | Q3: x | R3: x | S3: x
A4: 45989 | B4: Opaque_Materials & Window_Materials | C4: Confidence matching between Id's (create a new column for boverket and one for honeybee high-low confidence) | D4: Completed | I4: CMF_1960_1 | J4: x | K4: x | L4: x | M4: x | S4: x | T4: x | U4: x
A5: 45989 | B5: Opaque_Materials & Window_Materials | C5: Naming needs to be cleaned up; lowercase, no spaces no special characters...all similar and remove duplicates | D5: Completed | H5: Page 98 - 99 | I5: CMF_1960_2 | J5: x | K5: x | L5: x | M5: x | N5: x | R5: x | S5: x | U5: x
A6: 45989 | B6: Opaque_Materials & Window_Materials | C6: Double check that all of the honeybee materials are not of no mass type | D6: Pending | H6: Pages 112 - 113 | I6: CMF_1970 | J6: x | K6: x | L6: x | M6: x | S6: x | U6: x
A7: 45989 | B7: Layers | C7: split the layer names column into name and materials that its made up of | D7: Completed | H7: Pages 112 - 113 | I7: CMF_1980 | J7: x | K7: x | L7: x | M7: x | S7: x | U7: x
A8: 45989 | B8: Layers | C8: Identify which layers need to have a composite u-value (need area fraction), add flag (column) that signifies if its a composite layer or not | D8: Completed
A9: Friday, 5 December 2025 | B9: Opaque_Materials & Window_Materials | C9: add ignore column for red ones to keep track of not used materials | D9: Completed
A10: Friday, 5 December 2025 | B10: All Sheets | C10: Documentation/logbok when its finished to track process | D10: Pending
A11: Friday, 5 December 2025 | B11: Opaque_Materials & Window_Materials | C11: Mark the lowconfidence w pink | D11: Completed
A12: Thursday, 11 December 2025 | B12: Window_Materials | C12: Complete exteral database mapping and specifically to simple glazing materials in the Honeybee library and do a confidence scoring for the materials | D12: Maculated
A13: Thursday, 11 December 2025 | B13: All Sheets | C13: For the current archetypes, identify components, layers and materials for internal structures from the BUD_MI data | D13: Pending
A14: Thursday, 11 December 2025 | B14: Components | C14: Add column or switch out Component Name for a code describing the components similar to the Layer codes. Also Switch out the Layer identifier for the layer code instead | D14: Completed
A15: Thursday, 11 December 2025 | B15: Elements | C15: Make a sheet for Elements that should be combinations of components. Make sure to add a column for area ratio of component relative the total area of overall element | D15: Pending
A16: Thursday, 11 December 2025 | B16: Components | C16: Syncronise components in Excel with Enums in Python script | D16: Completed
A17: Thursday, 11 December 2025 | B17: Components | C17: Add component codes for all components and clean up window components so that they refer back to layers using simple glazing materials | D17: Completed
A18: Friday, 12 December 2025 | B18: Components | C18: For tall buildings, move no. Floors to notes and categorize between low, mid, high | D18: Completed
A19: Tuesday, 20 January 2026 | B19: Layers, Components | C19: Add data for CMF_1940_1 bottom floor from BUD_MI | D19: Completed
C22: Simulation workflow, what tests we have ran for sensitivty analysis. Why do we do these analysis? Cold attic, heating setpoints etc.
C23: Ask questions about renovation stratergies

Sheet Legend
A1: Formula (Only extend downwards when adding data)
A2: Optional Input
A3: Data Validation (Choose from dropdown list to ensure data is linked)
A4: Conditional Formatting
A5: Conditional Formatting
A6: Conditional Formatting
A7: Manual Input

Sheet Opaque_Materials
A1: Material Name | B1: Ignore? | C1: Boverket ID | D1: Boverket Match Confidence | E1: Honeybee Identifier | F1: Honeybee Match Confidence | G1: Combined Match Confidence
A2: Human-readable material name for the matched materials. | B2: An X if the material should be ignored/not used | C2: Boverket ID to inherit environmental impact values | D2: A confidence score (1-10) for how good the match between BUD_MI and Boverket is. | E2: Honeybee Materal name (identifier) to inherit thermal material properties | F2: A confidence score (1-10) for how good the match between BUD_MI and Honeybee is. | G2: Average confidence score between BUD_MI and Boverket and BUD_MI and Honeybee.
A3: wooden_stud | C3: 6000000007 | D3: 9 | E3: Std Wood 6 in. | F3: 9 | G3: =(D3+F3)/2 -> 9
A4: wooden_beam | C4: 6000000007 | D4: 9 | E4: Std Wood 6 in. | F4: 9 | G4: =(D4+F4)/2 -> 9
A5: wooden_rafter | C5: 6000000007 | D5: 9 | E5: Std Wood 6 in. | F5: 9 | G5: =(D5+F5)/2 -> 9
A6: wooden_panel | C6: 6000000007 | D6: 9 | E6: Std Wood 6 in. | F6: 9 | G6: =(D6+F6)/2 -> 9
A7: galvanized_sheet_metal | C7: 6000000221 | D7: 8 | E7: F08 Metal surface | F7: 6 | G7: =(D7+F7)/2 -> 7
A8: granulated_blast_furnace_slag | C8: 6000000085 | D8: 3 | E8: M11 100mm lightweight concrete | F8: 6 | G8: =(D8+F8)/2 -> 4.5
A9: concrete | C9: 6000000029 | D9: 9 | E9: 100mm Normalweight concrete floor | F9: 9 | G9: =(D9+F9)/2 -> 9
A10: lime_plaster | C10: 6000000094 | D10: 10 | E10: 25mm Stucco | F10: 10 | G10: =(D10+F10)/2 -> 10
A11: lightweight_concrete | C11: 6000000096 | D11: 8 | E11: M11 100mm lightweight concrete | F11: 10 | G11: =(D11+F11)/2 -> 9
A12: terrasit_plaster | C12: 6000000092 | D12: 9 | E12: 25mm Stucco | F12: 8 | G12: =(D12+F12)/2 -> 8.5
A13: mortar | C13: 6000000092 | D13: 9 | E13: 1IN Stucco | F13: 7 | G13: =(D13+F13)/2 -> 8
A14: plastic_mat | C14: 6000000210 | D14: 5 | E14: Roof Membrane | F14: 1 | G14: =(D14+F14)/2 -> 3
... A34: wooden_truss | C34: 6000000007 | D34: 8 | E34: Std Wood 6 in. | F34: 8 | G34: =(D34+F34)/2 -> 8
A35: reinforced concrete: steel | B35: X | C35: 6000000155 | D35: 10 | E35: F08 Metal surface | F35: 7 | G35: =(D35+F35)/2 -> 8.5
A36: asbestos_cement_board | C36: 6000000193 | D36: 3 | E36: Dry Dust | F36: 5 | G36: =(D36+F36)/2 -> 4
A37: foil | C37: 6000000198 | D37: 10 | E37: Roof Membrane | F37: 1 | G37: =(D37+F37)/2 -> 5.5
A38: gypsum_board | C38: 6000000020 | D38: 10 | E38: 5/8 in. Gypsum Board | F38: 10 | G38: =(D38+F38)/2 -> 10
A39: wooden_frame | C39: 6000000007 | D39: 8 | E39: Std Wood 6 in. | F39: 8 | G39: =(D39+F39)/2 -> 8
A40: lightweight_concrete_beam | B40: X | C40: 6000000096 | D40: 8 | E40: M11 100mm lightweight concrete | F40: 10 | G40: =(D40+F40)/2 -> 9
A41: beam_plate | B41: X | C41: 6000000221 | D41: 8 | E41: F08 Metal surface | F41: 9 | G41: =(D41+F41)/2 -> 8.5
A42: battens | C42: 6000000007 | D42: 8 | E42: Std Wood 6 in. | F42: 8 | G42: =(D42+F42)/2 -> 8
A43: ceramic_tile | C43: 6000000081 | D43: 5 | E43: HW CONCRETE | F43: 2 | G43: =(D43+F43)/2 -> 3.5
A44: paper | C44: 6000000141 | D44: 10 | E44: Roof Membrane | F44: 8 | G44: =(D44+F44)/2 -> 9
A45: wood_shavings | C45: 6000000000 | D45: 5 | E45: Wood Shavings (created) | F45: 5 | G45: =(D45+F45)/2 -> 5
A46: floorboard | C46: 6000000007 | D46: 10 | E46: Wood Siding | F46: 10 | G46: =(D46+F46)/2 -> 10
A47: vinyl_flooring | C47: 6000000224 | D47: 5 | E47: Roof Membrane | F47: 5 | G47: =(D47+F47)/2 -> 5
A48: membrane | C48: 6000000198 | D48: 7 | E48: Roof Membrane | F48: 8 | G48: =(D48+F48)/2 -> 7.5
A49: plaster | C49: 6000000091 | D49: 10 | E49: 1IN Stucco | F49: 10 | G49: =(D49+F49)/2 -> 10
A50: wooden frame pane windows | B50: X | C50: 6000000007 | D50: 8 | E50: Std Wood 6 in. | F50: 8 | G50: =(D50+F50)/2 -> 8
A51: wooden_frame | B51: X | C51: 6000000007 | D51: 8 | E51: Std Wood 6 in. | F51: 8 | G51: =(D51+F51)/2 -> 8
A52: cardboard | C52: 6000000141 | E52: Wood Siding | F52: 8 | G52: =(D52+F52)/2 -> 4
A53: concrete_tile | C53: 6000000081 | D53: 5 | E53: HW CONCRETE | F53: 2 | G53: =(D53+F53)/2 -> 3.5
A54: waterproof_membrane | C54: 6000000224 | D54: 4 | E54: Roof Membrane | F54: 5 | G54: =(D54+F54)/2 -> 4.5
A55: wood_wool_board | C55: 6000000222 | D55: 5 | E55: Cement Bonded Particleboard (created) | F55: 5 | G55: =(D55+F55)/2 -> 5
A56: sand | C56: 6000000084 | D56: 4 | E56: Dry Sand | F56: 9 | G56: =(D56+F56)/2 -> 6.5
A57: cellular_plastic | C57: 6000000210 | D57: 8 | E57: Roof Membrane | F57: 3 | G57: =(D57+F57)/2 -> 5.5
A58: gravel | C58: 6000000084 | D58: 2 | E58: Solid Rock | F58: 6 | G58: =(D58+F58)/2 -> 4
A59: plywood | C59: 6000000023 | D59: 10 | E59: Plywood - 5/8 in. CBES | F59: 10 | G59: =(D59+F59)/2 -> 10
...

Sheet Window_Materials
A1: Material Name | B1: Boverket ID | C1: Boverket Match Confidence | D1: EnergyPlus Identifier | E1: Honeybee Match Confidence | F1: Combined Match Confidence
A2: Human-readable material name for the matched materials. | B2: Boverket ID to inherit environmental impact values | C2: A confidence score (1-10) for how good the match between BUD_MI and Boverket is. | D2: Honeybee Materal name (identifier) to inherit thermal material properties | E2: A confidence score (1-10) for how good the match between BUD_MI and Honeybee is. | F2: Average confidence score between BUD_MI and Boverket and BUD_MI and Honeybee.
A3: Wooden frame | B3: 6000000007 | C3: 8 | D3: Std Wood 6 in. | E3: 8
A4: Glass | B4: 6000000122 | C4: 9 | D4: CLEAR 3MM | E4: 9
A5: wooden frame double pane windows | B5: 6000000007 | C5: 8 | D5: Std Wood 6 in. | E5: 8
A6: 2 pane glass | B6: 6000000122 | C6: 9 | D6: CLEAR 3MM | E6: 9
A7: 3 pane glass | B7: 6000000122 | C7: 9 | D7: CLEAR 3MM | E7: 9
A8: Wooden frame | B8: 6000000007 | C8: 8 | D8: Std Wood 6 in. | E8: 8
A12: Window, wood, fixed, 3-glass | B12: 6000000109 | D12: Std Wood 6 in.
D13: CLEAR 3MM

Sheet Layers
A1: Layer Code | B1: Layer Thickness | C1: Composite Layer? | D1: Material 1 | E1: Material 1 Area Ratio | F1: Material 2 | G1: Material 2 Area Ratio | H1: Material 3 | I1: Material 3 Area Ratio | J1: Notes from Så byggdes husen 1880-2010 | K1: Ignore? | L1: Layer Use Intesity | M1: Duplicate Check
A2: Layer code Material1_Material2_Thickness_SingleOrComposite | B2: Thickness of the layer in m. | C2: S for single material layer and C for composite layer | D2: If Composite Layer = No, Only this material column should be filled | E2: If Composite Layer = Yes: In-plane area ratio of material 1 in layer. | F2: If Composite Layer = Yes, this column should consist of the second material in the layer | G2: If Composite Layer = Yes: In-plane area ratio of material 2 in layer. | H2: If Composite Layer = Yes, this column should consist of the third material in the layer (if it exists) | I2: If Composite Layer = Yes: In-plane area ratio of material 3 in layer. | J2: Qualitative information about the layers. | K2: An X if the layer should be ignored/not used | L2: Represents how many times a layer is being used in the components sheet | M2: Returns how many times each layer occurs in this sheet. Should be 1 to avoid duplicate defenitons
A3: =UPPER(D3) &IF(F3<>"","_"&UPPER(F3),"") &IF(H3<>"","_"&UPPER(H3),"") &"_"&TRIM(_xlfn.TEXTAFTER(B3,",")) &"_"&C3 -> WOODEN_BEAM_1524_S | B3: 0.1524 | C3: S | D3: wooden_beam | J3: Spanning longside - long side | L3: =COUNTIF(Components!$B$3:$B$302,A3) -> 1 | M3: =COUNTIF($A$3:$A$308,A3) -> 1
A4: =UPPER(D4) &IF(F4<>"","_"&UPPER(F4),"") &IF(H4<>"","_"&UPPER(H4),"") &"_"&TRIM(_xlfn.TEXTAFTER(B4,",")) &"_"&C4 -> WOODEN_RAFTER_1016_S | B4: 0.1016 | C4: S | D4: wooden_rafter | J4: Resting on top wooden beams with c-c 1,2 m | L4: =COUNTIF(Components!$B$3:$B$302,A4) -> 1 | M4: =COUNTIF($A$3:$A$308,A4) -> 1
A5: =UPPER(D5) &IF(F5<>"","_"&UPPER(F5),"") &IF(H5<>"","_"&UPPER(H5),"") &"_"&TRIM(_xlfn.TEXTAFTER(B5,",")) &"_"&C5 -> WOODEN_PANEL_038_S | B5: 0.038 | C5: S | D5: wooden_panel | J5: Positioned directly under galvanized metal sheets | L5: =COUNTIF(Components!$B$3:$B$302,A5) -> 1 | M5: =COUNTIF($A$3:$A$308,A5) -> 1
A6: =UPPER(D6) &IF(F6<>"","_"&UPPER(F6),"") &IF(H6<>"","_"&UPPER(H6),"") &"_"&TRIM(_xlfn.TEXTAFTER(B6,",")) &"_"&C6 -> GALVANIZED_SHEET_METAL_003_S | B6: 0.003 | C6: S | D6: galvanized_sheet_metal | L6: =COUNTIF(Components!$B$3:$B$302,A6) -> 3 | M6: =COUNTIF($A$3:$A$308,A6) -> 1
A7: =UPPER(D7) &IF(F7<>"","_"&UPPER(F7),"") &IF(H7<>"","_"&UPPER(H7),"") &"_"&TRIM(_xlfn.TEXTAFTER(B7,",")) &"_"&C7 -> GRANULATED_BLAST_FURNACE_SLAG_15_S | B7: 0.15 | C7: S | D7: granulated_blast_furnace_slag | J7: Insulation layer | L7: =COUNTIF(Components!$B$3:$B$302,A7) -> 1 | M7: =COUNTIF($A$3:$A$308,A7) -> 1
A8: =UPPER(D8) &IF(F8<>"","_"&UPPER(F8),"") &IF(H8<>"","_"&UPPER(H8),"") &"_"&TRIM(_xlfn.TEXTAFTER(B8,",")) &"_"&C8 -> CONCRETE_14_S | B8: 0.14 | C8: S | D8: concrete | L8: =COUNTIF(Components!$B$3:$B$302,A8) -> 3 | M8: =COUNTIF($A$3:$A$308,A8) -> 1
A9: =UPPER(D9) &IF(F9<>"","_"&UPPER(F9),"") &IF(H9<>"","_"&UPPER(H9),"") &"_"&TRIM(_xlfn.TEXTAFTER(B9,",")) &"_"&C9 -> CONCRETE_15_S | B9: 0.15 | C9: S | D9: concrete | L9: =COUNTIF(Components!$B$3:$B$302,A9) -> 6 | M9: =COUNTIF($A$3:$A$308,A9) -> 1
A10: =UPPER(D10) &IF(F10<>"","_"&UPPER(F10),"") &IF(H10<>"","_"&UPPER(H10),"") &"_"&TRIM(_xlfn.TEXTAFTER(B10,",")) &"_"&C10 -> LIGHTWEIGHT_CONCRETE_MORTAR_125_C | B10: 0.125 | C10: C | D10: lightweight_concrete | E10: 0.95 | F10: mortar | G10: 0.05 | J10: Sharing the same space as mortar 12,5 cm vertically | L10: =COUNTIF(Components!$B$3:$B$302,A10) -> 1 | M10: =COUNTIF($A$3:$A$308,A10) -> 1
A11: =UPPER(D11) &IF(F11<>"","_"&UPPER(F11),"") &IF(H11<>"","_"&UPPER(H11),"") &"_"&TRIM(_xlfn.TEXTAFTER(B11,",")) &"_"&C11 -> TERRASIT_PLASTER_005_S | B11: 0.005 | C11: S | D11: terrasit_plaster | L11: =COUNTIF(Components!$B$3:$B$302,A11) -> 3 | M11: =COUNTIF($A$3:$A$308,A11) -> 1
A12: =UPPER(D12) &IF(F12<>"","_"&UPPER(F12),"") &IF(H12<>"","_"&UPPER(H12),"") &"_"&TRIM(_xlfn.TEXTAFTER(B12,",")) &"_"&C12 -> MORTAR_005_S | B12: 0.005 | C12: S | D12: mortar | J12: Was not specified in BUD_MI but in the book (however measurement is assumed) | L12: =COUNTIF(Components!$B$3:$B$302,A12) -> 1 | M12: =COUNTIF($A$3:$A$308,A12) -> 1
A13: =UPPER(D13) &IF(F13<>"","_"&UPPER(F13),"") &IF(H13<>"","_"&UPPER(H13),"") &"_"&TRIM(_xlfn.TEXTAFTER(B13,",")) &"_"&C13 -> LIME_PLASTER_005_S | B13: 0.005 | C13: S | D13: lime_plaster | L13: =COUNTIF(Components!$B$3:$B$302,A13) -> 2 | M13: =COUNTIF($A$3:$A$308,A13) -> 1
A14: =UPPER(D14) &IF(F14<>"","_"&UPPER(F14),"") &IF(H14<>"","_"&UPPER(H14),"") &"_"&TRIM(_xlfn.TEXTAFTER(B14,",")) &"_"&C14 -> LIGHTWEIGHT_CONCRETE_MORTAR_2_C | B14: 0.2 | C14: C | D14: lightweight_concrete | E14: 0.95 | F14: mortar | G14: 0.05 | J14: Assumed in accordance with other lightweight concrete/mortar structures for this building. | L14: =COUNTIF(Components!$B$3:$B$302,A14) -> 1 | M14: =COUNTIF($A$3:$A$308,A14) -> 1
A15: =UPPER(D15) &IF(F15<>"","_"&UPPER(F15),"") &IF(H15<>"","_"&UPPER(H15),"") &"_"&TRIM(_xlfn.TEXTAFTER(B15,",")) &"_"&C15 -> PLASTIC_MAT_01_S | B15: 0.01 | C15: S | D15: plastic_mat | L15: =COUNTIF(Components!$B$3:$B$302,A15) -> 6 | M15: =COUNTIF($A$3:$A$308,A15) -> 1
A16: =UPPER(D16) &IF(F16<>"","_"&UPPER(F16),"") &IF(H16<>"","_"&UPPER(H16),"") &"_"&TRIM(_xlfn.TEXTAFTER(B16,",")) &"_"&C16 -> PLASTER_005_S | B16: 0.005 | C16: S | D16: plaster | L16: =COUNTIF(Components!$B$3:$B$302,A16) -> 8 | M16: =COUNTIF($A$3:$A$308,A16) -> 1
A17: =UPPER(D17) &IF(F17<>"","_"&UPPER(F17),"") &IF(H17<>"","_"&UPPER(H17),"") &"_"&TRIM(_xlfn.TEXTAFTER(B17,",")) &"_"&C17 -> CONCRETE_16_S | B17: 0.16 | C17: S | D17: concrete | L17: =COUNTIF(Components!$B$3:$B$302,A17) -> 9 | M17: =COUNTIF($A$3:$A$308,A17) -> 1
A18: =UPPER(D18) &IF(F18<>"","_"&UPPER(F18),"") &IF(H18<>"","_"&UPPER(H18),"") &"_"&TRIM(_xlfn.TEXTAFTER(B18,",")) &"_"&C18 -> METAL_SHEET_003_S | B18: 0.003 | C18: S | D18: metal_sheet | L18: =COUNTIF(Components!$B$3:$B$302,A18) -> 2 | M18: =COUNTIF($A$3:$A$308,A18) -> 1
A19: =UPPER(D19) &IF(F19<>"","_"&UPPER(F19),"") &IF(H19<>"","_"&UPPER(H19),"") &"_"&TRIM(_xlfn.TEXTAFTER(B19,",")) &"_"&C19 -> BATTENS_1_023_S | B19: 0.023 | C19: S | D19: battens_1 | L19: =COUNTIF(Components!$B$3:$B$302,A19) -> 1 | M19: =COUNTIF($A$3:$A$308,A19) -> 1
A20: =UPPER(D20) &IF(F20<>"","_"&UPPER(F20),"") &IF(H20<>"","_"&UPPER(H20),"") &"_"&TRIM(_xlfn.TEXTAFTER(B20,",")) &"_"&C20 -> BATTENS_2_023_S | B20: 0.023 | C20: S | D20: battens_2 | L20: =COUNTIF(Components!$B$3:$B$302,A20) -> 1 | M20: =COUNTIF($A$3:$A$308,A20) -> 1
A21: =UPPER(D21) &IF(F21<>"","_"&UPPER(F21),"") &IF(H21<>"","_"&UPPER(H21),"") &"_"&TRIM(_xlfn.TEXTAFTER(B21,",")) &"_"&C21 -> ROOFING_FELT_005_S | B21: 0.005 | C21: S | D21: roofing_felt | L21: =COUNTIF(Components!$B$3:$B$302,A21) -> 1 | M21: =COUNTIF($A$3:$A$308,A21) -> 1
A22: =UPPER(D22) &IF(F22<>"","_"&UPPER(F22),"") &IF(H22<>"","_"&UPPER(H22),"") &"_"&TRIM(_xlfn.TEXTAFTER(B22,",")) &"_"&C22 -> WOODEN_PANEL_0254_S | B22: 0.0254 | C22: S | D22: wooden_panel | L22: =COUNTIF(Components!$B$3:$B$302,A22) -> 0 | M22: =COUNTIF($A$3:$A$308,A22) -> 1
A23: =UPPER(D23) &IF(F23<>"","_"&UPPER(F23),"") &IF(H23<>"","_"&UPPER(H23),"") &"_"&TRIM(_xlfn.TEXTAFTER(B23,",")) &"_"&C23 -> BRICK_MORTAR_125_C | B23: 0.125 | C23: C | D23: brick | E23: 0.85 | F23: mortar | G23: 0.15 | L23: =COUNTIF(Components!$B$3:$B$302,A23) -> 1 | M23: =COUNTIF($A$3:$A$308,A23) -> 1
A24: =UPPER(D24) &IF(F24<>"","_"&UPPER(F24),"") &IF(H24<>"","_"&UPPER(H24),"") &"_"&TRIM(_xlfn.TEXTAFTER(B24,",")) &"_"&C24 -> MINERAL_WOOL_WOODEN_STUD_095_C | B24: 0.095 | C24: C | D24: mineral_wool | E24: 0.9 | F24: wooden_stud | G24: 0.1 | J24: Assumed to be parallel vertically with studs and therefore has the same thickness, original thickness in BUD_MI was 5 cm | L24: =COUNTIF(Components!$B$3:$B$302,A24) -> 1 | M24: =COUNTIF($A$3:$A$308,A24) -> 1
A25: =UPPER(D25) &IF(F25<>"","_"&UPPER(F25),"") &IF(H25<>"","_"&UPPER(H25),"") &"_"&TRIM(_xlfn.TEXTAFTER(B25,",")) &"_"&C25 -> ETERNIT_BOARD_009_S | B25: 0.009 | C25: S | D25: eternit_board | L25: =COUNTIF(Components!$B$3:$B$302,A25) -> 1 | M25: =COUNTIF($A$3:$A$308,A25) -> 1
A26: =UPPER(D26) &IF(F26<>"","_"&UPPER(F26),"") &IF(H26<>"","_"&UPPER(H26),"") &"_"&TRIM(_xlfn.TEXTAFTER(B26,",")) &"_"&C26 -> ASPHALT_BOARD_012_S | B26: 0.012 | C26: S | D26: asphalt_board | L26: =COUNTIF(Components!$B$3:$B$302,A26) -> 1 | M26: =COUNTIF($A$3:$A$308,A26) -> 1
A27: =UPPER(D27) &IF(F27<>"","_"&UPPER(F27),"") &IF(H27<>"","_"&UPPER(H27),"") &"_"&TRIM(_xlfn.TEXTAFTER(B27,",")) &"_"&C27 -> PLASTER_BOARD_013_S | B27: 0.013 | C27: S | D27: plaster_board | L27: =COUNTIF(Components!$B$3:$B$302,A27) -> 2 | M27: =COUNTIF($A$3:$A$308,A27) -> 1
A28: =UPPER(D28) &IF(F28<>"","_"&UPPER(F28),"") &IF(H28<>"","_"&UPPER(H28),"") &"_"&TRIM(_xlfn.TEXTAFTER(B28,",")) &"_"&C28 -> LINOLEUM_01_S | B28: 0.01 | C28: S | D28: linoleum | L28: =COUNTIF(Components!$B$3:$B$302,A28) -> 4 | M28: =COUNTIF($A$3:$A$308,A28) -> 1
A29: =UPPER(D29) &IF(F29<>"","_"&UPPER(F29),"") &IF(H29<>"","_"&UPPER(H29),"") &"_"&TRIM(_xlfn.TEXTAFTER(B29,",")) &"_"&C29 -> LECA_15_S | B29: 0.15 | C29: S | D29: leca | L29: =COUNTIF(Components!$B$3:$B$302,A29) -> 1 | M29: =COUNTIF($A$3:$A$308,A29) -> 1
A30: =UPPER(D30) &IF(F30<>"","_"&UPPER(F30),"") &IF(H30<>"","_"&UPPER(H30),"") &"_"&TRIM(_xlfn.TEXTAFTER(B30,",")) &"_"&C30 -> CARDBOARD_005_S | B30: 0.005 | C30: S | D30: cardboard | L30: =COUNTIF(Components!$B$3:$B$302,A30) -> 2 | M30: =COUNTIF($A$3:$A$308,A30) -> 1
A31: =UPPER(D31) &IF(F31<>"","_"&UPPER(F31),"") &IF(H31<>"","_"&UPPER(H31),"") &"_"&TRIM(_xlfn.TEXTAFTER(B31,",")) &"_"&C31 -> MINERAL_WOOL_BLANKET_03_S | B31: 0.03 | C31: S | D31: mineral_wool_blanket | L31: =COUNTIF(Components!$B$3:$B$302,A31) -> 2 | M31: =COUNTIF($A$3:$A$308,A31) -> 1
A32: =UPPER(D32) &IF(F32<>"","_"&UPPER(F32),"") &IF(H32<>"","_"&UPPER(H32),"") &"_"&TRIM(_xlfn.TEXTAFTER(B32,",")) &"_"&C32 -> MINERAL_WOOL_CARPET_2_S | B32: 0.2 | C32: S | D32: mineral_wool_carpet | L32: =COUNTIF(Components!$B$3:$B$302,A32) -> 1 | M32: =COUNTIF($A$3:$A$308,A32) -> 1
A33: =UPPER(D33) &IF(F33<>"","_"&UPPER(F33),"") &IF(H33<>"","_"&UPPER(H33),"") &"_"&TRIM(_xlfn.TEXTAFTER(B33,",")) &"_"&C33 -> ROOFING_FELT_01_S | B33: 0.01 | C33: S | D33: roofing_felt | L33: =COUNTIF(Components!$B$3:$B$302,A33) -> 1 | M33: =COUNTIF($A$3:$A$308,A33) -> 1
A34: =UPPER(D34) &IF(F34<>"","_"&UPPER(F34),"") &IF(H34<>"","_"&UPPER(H34),"") &"_"&TRIM(_xlfn.TEXTAFTER(B34,",")) &"_"&C34 -> WOODEN_TRUSS_05_S | B34: 0.05 | C34: S | D34: wooden_truss | K34: X | L34: =COUNTIF(Components!$B$3:$B$302,A34) -> 1 | M34: =COUNTIF($A$3:$A$308,A34) -> 1
A35: =UPPER(D35) &IF(F35<>"","_"&UPPER(F35),"") &IF(H35<>"","_"&UPPER(H35),"") &"_"&TRIM(_xlfn.TEXTAFTER(B35,",")) &"_"&C35 -> LIGHTWEIGHT_CONCRETE_MORTAR_15_C | B35: 0.15 | C35: C | D35: lightweight_concrete | E35: 0.95 | F35: mortar | G35: 0.05 | L35: =COUNTIF(Components!$B$3:$B$302,A35) -> 1 | M35: =COUNTIF($A$3:$A$308,A35) -> 1
A36: =UPPER(D36) &IF(F36<>"","_"&UPPER(F36),"") &IF(H36<>"","_"&UPPER(H36),"") &"_"&TRIM(_xlfn.TEXTAFTER(B36,",")) &"_"&C36 -> ASBESTOS_CEMENT_BOARD_01_S | B36: 0.01 | C36: S | D36: asbestos_cement_board | L36: =COUNTIF(Components!$B$3:$B$302,A36) -> 1 | M36: =COUNTIF($A$3:$A$308,A36) -> 1
A37: =UPPER(D37) &IF(F37<>"","_"&UPPER(F37),"") &IF(H37<>"","_"&UPPER(H37),"") &"_"&TRIM(_xlfn.TEXTAFTER(B37,",")) &"_"&C37 -> ASPHALT_BOARD_01_S | B37: 0.01 | C37: S | D37: asphalt_board | L37: =COUNTIF(Components!$B$3:$B$302,A37) -> 1 | M37: =COUNTIF($A$3:$A$308,A37) -> 1
A38: =UPPER(D38) &IF(F38<>"","_"&UPPER(F38),"") &IF(H38<>"","_"&UPPER(H38),"") &"_"&TRIM(_xlfn.TEXTAFTER(B38,",")) &"_"&C38 -> MINERAL_WOOL_WOODEN_STUD_05_C | B38: 0.05 | C38: C | D38: mineral_wool | E38: 0.9 | F38: wooden_stud | G38: 0.1 | J38: Not sure about this measurement | L38: =COUNTIF(Components!$B$3:$B$302,A38) -> 1 | M38: =COUNTIF($A$3:$A$308,A38) -> 1
A39: =UPPER(D39) &IF(F39<>"","_"&UPPER(F39),"") &IF(H39<>"","_"&UPPER(H39),"") &"_"&TRIM(_xlfn.TEXTAFTER(B39,",")) &"_"&C39 -> FOIL_001_S | B39: 0.001 | C39: S | D39: foil | L39: =COUNTIF(Components!$B$3:$B$302,A39) -> 2 | M39: =COUNTIF($A$3:$A$308,A39) -> 1
A40: =UPPER(D40) &IF(F40<>"","_"&UPPER(F40),"") &IF(H40<>"","_"&UPPER(H40),"") &"_"&TRIM(_xlfn.TEXTAFTER(B40,",")) &"_"&C40 -> BATTENS_1_04_S | B40: 0.04 | C40: S | D40: battens_1 | L40: =COUNTIF(Components!$B$3:$B$302,A40) -> 1 | M40: =COUNTIF($A$3:$A$308,A40) -> 1
...

Sheet Components
A1: Component Code | B1: Layers | C1: Application | D1: Layer Index | E1: Shearing Layer | F1: Archetype | G1: Notes from Så byggdes husen 1880-2010 | H1: Flag
A2: Component code Archetype_Application_ShearingLayer | B2: Order of layer from exterior to interior | C2: Element where component is applicable | D2: Index of layer, from exterior to interior where 0 is most exterior | E2: Shearing Layer as in Brand model | F2: Code for archetype inhertied from BUD_MI | G2: Qualitative information about the components. | H2: Counts how many times a layer defined in this sheet exists in Layers sheet, if none, "No match"
A3: =F3&"_"&C3&"_"&E3 -> CMF_1950_ROOF_SKIN | B3: GALVANIZED_SHEET_METAL_003_S | C3: ROOF | D3: 0 | E3: SKIN | F3: CMF_1950 | G3: Cold roof, no insulation as part of outermost structure | H3: {=IF(SUMPRODUCT(--EXACT(B3,Layers!$A$3:$A$268))=0,"No match",SUMPRODUCT(--EXACT(B3,Layers!$A$3:$A$268)))} -> 1
A4: =F4&"_"&C4&"_"&E4 -> CMF_1950_ROOF_SKIN | B4: WOODEN_PANEL_038_S | C4: ROOF | D4: 1 | E4: SKIN | F4: CMF_1950 | H4: {=IF(SUMPRODUCT(--EXACT(B4,Layers!$A$3:$A$268))=0,"No match",SUMPRODUCT(--EXACT(B4,Layers!$A$3:$A$268)))} -> 1
A5: =F5&"_"&C5&"_"&E5 -> CMF_1950_ROOF_STRUCTURE | B5: WOODEN_RAFTER_1016_S | C5: ROOF | D5: 0 | E5: STRUCTURE | F5: CMF_1950 | G5: Minor impact on thermal performance of roof structure as they are not interupting any insulation layer. | H5: {=IF(SUMPRODUCT(--EXACT(B5,Layers!$A$3:$A$268))=0,"No match",SUMPRODUCT(--EXACT(B5,Layers!$A$3:$A$268)))} -> 1
A6: =F6&"_"&C6&"_"&E6 -> CMF_1950_ROOF_STRUCTURE | B6: WOODEN_BEAM_1524_S | C6: ROOF | D6: 1 | E6: STRUCTURE | F6: CMF_1950 | H6: {=IF(SUMPRODUCT(--EXACT(B6,Layers!$A$3:$A$268))=0,"No match",SUMPRODUCT(--EXACT(B6,Layers!$A$3:$A$268)))} -> 1
A7: =F7&"_"&C7&"_"&E7 -> CMF_1950_TOP_FLOOR_SPACE | B7: CONCRETE_05_S | C7: TOP_FLOOR | D7: 0 | E7: SPACE | F7: CMF_1950 | G7: Insulating "roof" structure | H7: {=IF(SUMPRODUCT(--EXACT(B7,Layers!$A$3:$A$268))=0,"No match",SUMPRODUCT(--EXACT(B7,Layers!$A$3:$A$268)))} -> 1
A8: =F8&"_"&C8&"_"&E8 -> CMF_1950_TOP_FLOOR_SPACE | B8: GRANULATED_BLAST_FURNACE_SLAG_15_S | C8: TOP_FLOOR | D8: 1 | E8: SPACE | F8: CMF_1950 | H8: {=IF(SUMPRODUCT(--EXACT(B8,Layers!$A$3:$A$268))=0,"No match",SUMPRODUCT(--EXACT(B8,Layers!$A$3:$A$268)))} -> 1
A9: =F9&"_"&C9&"_"&E9 -> CMF_1950_TOP_FLOOR_STRUCTURE | B9: CONCRETE_14_S | C9: TOP_FLOOR | D9: 0 | E9: STRUCTURE | F9: CMF_1950 | H9: {=IF(SUMPRODUCT(--EXACT(B9,Layers!$A$3:$A$268))=0,"No match",SUMPRODUCT(--EXACT(B9,Layers!$A$3:$A$268)))} -> 1
A10: =F10&"_"&C10&"_"&E10 -> CMF_1950_EXT_WALL_LOW_SKIN | B10: TERRASIT_PLASTER_005_S | C10: EXT_WALL_LOW | D10: 0 | E10: SKIN | F10: CMF_1950 | H10: {=IF(SUMPRODUCT(--EXACT(B10,Layers!$A$3:$A$268))=0,"No match",SUMPRODUCT(--EXACT(B10,Layers!$A$3:$A$268)))} -> 1
A11: =F11&"_"&C11&"_"&E11 -> CMF_1950_EXT_WALL_LOW_STRUCTURE | B11: LIGHTWEIGHT_CONCRETE_MORTAR_125_C | C11: EXT_WALL_LOW | D11: 0 | E11: STRUCTURE | F11: CMF_1950 | H11: {=IF(SUMPRODUCT(--EXACT(B11,Layers!$A$3:$A$268))=0,"No match",SUMPRODUCT(--EXACT(B11,Layers!$A$3:$A$268)))} -> 1
A12: =F12&"_"&C12&"_"&E12 -> CMF_1950_EXT_WALL_LOW_STRUCTURE | B12: MORTAR_005_S | C12: EXT_WALL_LOW | D12: 1 | E12: STRUCTURE | F12: CMF_1950 | H12: {=IF(SUMPRODUCT(--EXACT(B12,Layers!$A$3:$A$268))=0,"No match",SUMPRODUCT(--EXACT(B12,Layers!$A$3:$A$268)))} -> 1
A13: =F13&"_"&C13&"_"&E13 -> CMF_1950_EXT_WALL_LOW_STRUCTURE | B13: CONCRETE_15_S | C13: EXT_WALL_LOW | D13: 2 | E13: STRUCTURE | F13: CMF_1950 | H13: {=IF(SUMPRODUCT(--EXACT(B13,Layers!$A$3:$A$268))=0,"No match",SUMPRODUCT(--EXACT(B13,Layers!$A$3:$A$268)))} -> 1
A14: =F14&"_"&C14&"_"&E14 -> CMF_1950_EXT_WALL_LOW_SPACE | B14: LIME_PLASTER_005_S | C14: EXT_WALL_LOW | D14: 0 | E14: SPACE | F14: CMF_1950 | H14: {=IF(SUMPRODUCT(--EXACT(B14,Layers!$A$3:$A$268))=0,"No match",SUMPRODUCT(--EXACT(B14,Layers!$A$3:$A$268)))} -> 1
A15: =F15&"_"&C15&"_"&E15 -> CMF_1950_EXT_WALL_MEDIUM_SKIN | B15: TERRASIT_PLASTER_005_S | C15: EXT_WALL_MEDIUM | D15: 0 | E15: SKIN | F15: CMF_1950 | H15: {=IF(SUMPRODUCT(--EXACT(B15,Layers!$A$3:$A$268))=0,"No match",SUMPRODUCT(--EXACT(B15,Layers!$A$3:$A$268)))} -> 1
A16: =F16&"_"&C16&"_"&E16 -> CMF_1950_EXT_WALL_MEDIUM_STRUCTURE | B16: LIGHTWEIGHT_CONCRETE_MORTAR_25_C | C16: EXT_WALL_MEDIUM | D16: 0 | E16: STRUCTURE | F16: CMF_1950 | H16: {=IF(SUMPRODUCT(--EXACT(B16,Layers!$A$3:$A$268))=0,"No match",SUMPRODUCT(--EXACT(B16,Layers!$A$3:$A$268)))} -> 1
A17: =F17&"_"&C17&"_"&E17 -> CMF_1950_EXT_WALL_MEDIUM_SPACE | B17: LIME_PLASTER_005_S | C17: EXT_WALL_MEDIUM | D17: 0 | E17: SPACE | F17: CMF_1950 | H17: {=IF(SUMPRODUCT(--EXACT(B17,Layers!$A$3:$A$268))=0,"No match",SUMPRODUCT(--EXACT(B17,Layers!$A$3:$A$268)))} -> 1
A18: =F18&"_"&C18&"_"&E18 -> CMF_1950_EXT_WALL_HIGH_SKIN | B18: TERRASIT_PLASTER_005_S | C18: EXT_WALL_HIGH | D18: 0 | E18: SKIN | F18: CMF_1950 | G18: Was missing from BUD_MI | H18: {=IF(SUMPRODUCT(--EXACT(B18,Layers!$A$3:$A$268))=0,"No match",SUMPRODUCT(--EXACT(B18,Layers!$A$3:$A$268)))} -> 1
A19: =F19&"_"&C19&"_"&E19 -> CMF_1950_EXT_WALL_HIGH_STRUCTURE | B19: LIGHTWEIGHT_CONCRETE_MORTAR_2_C | C19: EXT_WALL_HIGH | D19: 0 | E19: STRUCTURE | F19: CMF_1950 | G19: Was missing from BUD_MI | H19: {=IF(SUMPRODUCT(--EXACT(B19,Layers!$A$3:$A$268))=0,"No match",SUMPRODUCT(--EXACT(B19,Layers!$A$3:$A$268)))} -> 1
A20: =F20&"_"&C20&"_"&E20 -> CMF_1950_GROUND_FLOOR_SPACE | B20: PLASTIC_MAT_01_S | C20: GROUND_FLOOR | D20: 0 | E20: SPACE | F20: CMF_1950 | H20: {=IF(SUMPRODUCT(--EXACT(B20,Layers!$A$3:$A$268))=0,"No match",SUMPRODUCT(--EXACT(B20,Layers!$A$3:$A$268)))} -> 1
A21: =F21&"_"&C21&"_"&E21 -> CMF_1950_GROUND_FLOOR_SPACE | B21: PLASTER_05_S | C21: GROUND_FLOOR | D21: 1 | E21: SPACE | F21: CMF_1950 | H21: {=IF(SUMPRODUCT(--EXACT(B21,Layers!$A$3:$A$268))=0,"No match",SUMPRODUCT(--EXACT(B21,Layers!$A$3:$A$268)))} -> 1
A22: =F22&"_"&C22&"_"&E22 -> CMF_1950_GROUND_FLOOR_STRUCTURE | B22: CONCRETE_MIXED_WITH_SAWDUST_05_S | C22: GROUND_FLOOR | D22: 0 | E22: STRUCTURE | F22: CMF_1950 | H22: {=IF(SUMPRODUCT(--EXACT(B22,Layers!$A$3:$A$268))=0,"No match",SUMPRODUCT(--EXACT(B22,Layers!$A$3:$A$268)))} -> 1
A23: =F23&"_"&C23&"_"&E23 -> CMF_1950_GROUND_FLOOR_STRUCTURE | B23: COKE_ASH_08_S | C23: GROUND_FLOOR | D23: 1 | E23: STRUCTURE | F23: CMF_1950 | H23: {=IF(SUMPRODUCT(--EXACT(B23,Layers!$A$3:$A$268))=0,"No match",SUMPRODUCT(--EXACT(B23,Layers!$A$3:$A$268)))} -> 1
A24: =F24&"_"&C24&"_"&E24 -> CMF_1950_GROUND_FLOOR_STRUCTURE | B24: CONCRETE_16_S | C24: GROUND_FLOOR | D24: 2 | E24: STRUCTURE | F24: CMF_1950 | H24: {=IF(SUMPRODUCT(--EXACT(B24,Layers!$A$3:$A$268))=0,"No match",SUMPRODUCT(--EXACT(B24,Layers!$A$3:$A$268)))} -> 1
A25: =F25&"_"&C25&"_"&E25 -> CMF_1950_INT_WALL_NONLOADBEARING_SKIN | B25: PLASTER_05_S | C25: INT_WALL_NONLOADBEARING | D25: 0 | E25: SKIN | F25: CMF_1950 | H25: {=IF(SUMPRODUCT(--EXACT(B25,Layers!$A$3:$A$268))=0,"No match",SUMPRODUCT(--EXACT(B25,Layers!$A$3:$A$268)))} -> 1
A26: =F26&"_"&C26&"_"&E26 -> CMF_1950_INT_WALL_NONLOADBEARING_STRUCTURE | C26: INT_WALL_NONLOADBEARING | D26: 0 | E26: STRUCTURE | F26: CMF_1950 | G26: No souce found | H26: {=IF(SUMPRODUCT(--EXACT(B26,Layers!$A$3:$A$268))=0,"No match",SUMPRODUCT(--EXACT(B26,Layers!$A$3:$A$268)))} -> 186
A27: =F27&"_"&C27&"_"&E27 -> CMF_1950_INT_WALL_NONLOADBEARING_SPACE | C27: INT_WALL_NONLOADBEARING | D27: 0 | E27: SPACE | F27: CMF_1950 | G27: No souce found | H27: {=IF(SUMPRODUCT(--EXACT(B27,Layers!$A$3:$A$268))=0,"No match",SUMPRODUCT(--EXACT(B27,Layers!$A$3:$A$268)))} -> 186
A28: =F28&"_"&C28&"_"&E28 -> CMF_1950_INT_WALL_NONLOADBEARING_STRUCTURE | C28: INT_WALL_NONLOADBEARING | D28: 0 | E28: STRUCTURE | F28: CMF_1950 | G28: No souce found | H28: {=IF(SUMPRODUCT(--EXACT(B28,Layers!$A$3:$A$268))=0,"No match",SUMPRODUCT(--EXACT(B28,Layers!$A$3:$A$268)))} -> 186
A29: =F29&"_"&C29&"_"&E29 -> CMF_1950_INTERMEDIATE_FLOOR_SPACE | B29: PLASTIC_MAT_01_S | C29: INTERMEDIATE_FLOOR | D29: 0 | E29: SPACE | F29: CMF_1950 | H29: {=IF(SUMPRODUCT(--EXACT(B29,Layers!$A$3:$A$268))=0,"No match",SUMPRODUCT(--EXACT(B29,Layers!$A$3:$A$268)))} -> 1
A30: =F30&"_"&C30&"_"&E30 -> CMF_1950_INTERMEDIATE_FLOOR_SPACE | B30: CONCRETE_MIXED_WITH_SAWDUST_05_S | C30: INTERMEDIATE_FLOOR | D30: 1 | E30: SPACE | F30: CMF_1950 | H30: {=IF(SUMPRODUCT(--EXACT(B30,Layers!$A$3:$A$268))=0,"No match",SUMPRODUCT(--EXACT(B30,Layers!$A$3:$A$268)))} -> 1
A31: =F31&"_"&C31&"_"&E31 -> CMF_1950_INTERMEDIATE_FLOOR_SPACE | B31: COKE_ASH_08_S | C31: INTERMEDIATE_FLOOR | D31: 2 | E31: SPACE | F31: CMF_1950 | H31: {=IF(SUMPRODUCT(--EXACT(B31,Layers!$A$3:$A$268))=0,"No match",SUMPRODUCT(--EXACT(B31,Layers!$A$3:$A$268)))} -> 1
A32: =F32&"_"&C32&"_"&E32 -> CMF_1950_INTERMEDIATE_FLOOR_STRUCTURE | B32: CONCRETE_16_S | C32: INTERMEDIATE_FLOOR | D32: 0 | E32: STRUCTURE | F32: CMF_1950 | H32: {=IF(SUMPRODUCT(--EXACT(B32,Layers!$A$3:$A$268))=0,"No match",SUMPRODUCT(--EXACT(B32,Layers!$A$3:$A$268)))} -> 1
A33: =F33&"_"&C33&"_"&E33 -> CMF_1950_INTERMEDIATE_FLOOR_SPACE | B33: PLASTER_005_S | C33: INTERMEDIATE_FLOOR | D33: 0 | E33: SPACE | F33: CMF_1950 | H33: {=IF(SUMPRODUCT(--EXACT(B33,Layers!$A$3:$A$268))=0,"No match",SUMPRODUCT(--EXACT(B33,Layers!$A$3:$A$268)))} -> 1
A34: =F34&"_"&C34&"_"&E34 -> CMF_1960_1_ROOF_SKIN | B34: METAL_SHEET_003_S | C34: ROOF | D34: 0 | E34: SKIN | F34: CMF_1960_1 | H34: {=IF(SUMPRODUCT(--EXACT(B34,Layers!$A$3:$A$268))=0,"No match",SUMPRODUCT(--EXACT(B34,Layers!$A$3:$A$268)))} -> 1
A35: =F35&"_"&C35&"_"&E35 -> CMF_1960_1_ROOF_SKIN | B35: BATTENS_1_023_S | C35: ROOF | D35: 1 | E35: SKIN | F35: CMF_1960_1 | G35: Double check in book | H35: {=IF(SUMPRODUCT(--EXACT(B35,Layers!$A$3:$A$268))=0,"No match",SUMPRODUCT(--EXACT(B35,Layers!$A$3:$A$268)))} -> 1
A36: =F36&"_"&C36&"_"&E36 -> CMF_1960_1_ROOF_SKIN | B36: BATTENS_2_023_S | C36: ROOF | D36: 2 | E36: SKIN | F36: CMF_1960_1 | G36: Double check in book | H36: {=IF(SUMPRODUCT(--EXACT(B36,Layers!$A$3:$A$268))=0,"No match",SUMPRODUCT(--EXACT(B36,Layers!$A$3:$A$268)))} -> 1
A37: =F37&"_"&C37&"_"&E37 -> CMF_1960_1_ROOF_SKIN | B37: ROOFING_FELT_005_S | C37: ROOF | D37: 3 | E37: SKIN | F37: CMF_1960_1 | H37: {=IF(SUMPRODUCT(--EXACT(B37,Layers!$A$3:$A$268))=0,"No match",SUMPRODUCT(--EXACT(B37,Layers!$A$3:$A$268)))} -> 1
A38: =F38&"_"&C38&"_"&E38 -> CMF_1960_1_ROOF_SKIN | B38: WOODEN_PANEL_03_S | C38: ROOF | D38: 4 | E38: SKIN | F38: CMF_1960_1 | H38: {=IF(SUMPRODUCT(--EXACT(B38,Layers!$A$3:$A$268))=0,"No match",SUMPRODUCT(--EXACT(B38,Layers!$A$3:$A$268)))} -> 1
A39: =F39&"_"&C39&"_"&E39 -> CMF_1960_1_EXT_WALL_SKIN | B39: BRICK_MORTAR_125_C | C39: EXT_WALL | D39: 0 | E39: SKIN | F39: CMF_1960_1 | H39: {=IF(SUMPRODUCT(--EXACT(B39,Layers!$A$3:$A$268))=0,"No match",SUMPRODUCT(--EXACT(B39,Layers!$A$3:$A$268)))} -> 1
A40: =F40&"_"&C40&"_"&E40 -> CMF_1960_1_EXT_WALL_SPACE | B40: PLASTER_BOARD_013_S | C40: EXT_WALL | D40: 0 | E40: SPACE | F40: CMF_1960_1 | H40: {=IF(SUMPRODUCT(--EXACT(B40,Layers!$A$3:$A$268))=0,"No match",SUMPRODUCT(--EXACT(B40,Layers!$A$3:$A$268)))} -> 1
...

Sheet Elements
A1: Element Code | B1: Element type | C1: Archetype | D1: Components
A2: A code for the element used as reference for the element in the Building sheet | B2: A finite list of elements to choose from to create a full building defenition | C2: Code for archetype inhertied from BUD_MI | D2: The components used in each element
A3: =C3&"_"&B3 -> CMF_1950_ROOF | B3: ROOF | C3: CMF_1950 | D3: {=IFERROR(TRANSPOSE(_xlfn._xlws.FILTER(Components!$A$3:$A$302,(Components!$C$3:$C$302=B3)*(Components!$F$3:$F$302=C3))),"No matches found")} -> CMF_1950_ROOF_SKIN | E3: CMF_1950_ROOF_SKIN | F3: CMF_1950_ROOF_STRUCTURE | G3: CMF_1950_ROOF_STRUCTURE
A4: =C4&"_"&B4 -> CMF_1950_TOP_FLOOR | B4: TOP_FLOOR | C4: CMF_1950 | D4: {=IFERROR(TRANSPOSE(_xlfn._xlws.FILTER(Components!$A$3:$A$302,(Components!$C$3:$C$302=B4)*(Components!$F$3:$F$302=C4))),"No matches found")} -> CMF_1950_TOP_FLOOR_SPACE | E4: CMF_1950_TOP_FLOOR_SPACE | F4: CMF_1950_TOP_FLOOR_STRUCTURE
A5: =C5&"_"&B5 -> CMF_1950_INTERMEDIATE_FLOOR | B5: INTERMEDIATE_FLOOR | C5: CMF_1950 | D5: {=IFERROR(TRANSPOSE(_xlfn._xlws.FILTER(Components!$A$3:$A$302,(Components!$C$3:$C$302=B5)*(Components!$F$3:$F$302=C5))),"No matches found")} -> CMF_1950_INTERMEDIATE_FLOOR_SPACE | E5: CMF_1950_INTERMEDIATE_FLOOR_SPACE | F5: CMF_1950_INTERMEDIATE_FLOOR_SPACE | G5: CMF_1950_INTERMEDIATE_FLOOR_STRUCTURE | H5: CMF_1950_INTERMEDIATE_FLOOR_SPACE
A6: =C6&"_"&B6 -> CMF_1950_GROUND_FLOOR | B6: GROUND_FLOOR | C6: CMF_1950 | D6: {=IFERROR(TRANSPOSE(_xlfn._xlws.FILTER(Components!$A$3:$A$302,(Components!$C$3:$C$302=B6)*(Components!$F$3:$F$302=C6))),"No matches found")} -> CMF_1950_GROUND_FLOOR_SPACE | E6: CMF_1950_GROUND_FLOOR_SPACE | F6: CMF_1950_GROUND_FLOOR_STRUCTURE | G6: CMF_1950_GROUND_FLOOR_STRUCTURE | H6: CMF_1950_GROUND_FLOOR_STRUCTURE
A7: =C7&"_"&B7 -> CMF_1950_BASEMENT_FLOOR | B7: BASEMENT_FLOOR | C7: CMF_1950 | D7: {=IFERROR(TRANSPOSE(_xlfn._xlws.FILTER(Components!$A$3:$A$302,(Components!$C$3:$C$302=B7)*(Components!$F$3:$F$302=C7))),"No matches found")} -> CMF_1950_BASEMENT_FLOOR_STRUCTURE
A8: =C8&"_"&B8 -> CMF_1950_EXT_WALL_LOW | B8: EXT_WALL_LOW | C8: CMF_1950 | D8: {=IFERROR(TRANSPOSE(_xlfn._xlws.FILTER(Components!$A$3:$A$302,(Components!$C$3:$C$302=B8)*(Components!$F$3:$F$302=C8))),"No matches found")} -> CMF_1950_EXT_WALL_LOW_SKIN | E8: CMF_1950_EXT_WALL_LOW_STRUCTURE | F8: CMF_1950_EXT_WALL_LOW_STRUCTURE | G8: CMF_1950_EXT_WALL_LOW_STRUCTURE | H8: CMF_1950_EXT_WALL_LOW_SPACE
A9: =C9&"_"&B9 -> CMF_1950_EXT_WALL_MEDIUM | B9: EXT_WALL_MEDIUM | C9: CMF_1950 | D9: {=IFERROR(TRANSPOSE(_xlfn._xlws.FILTER(Components!$A$3:$A$302,(Components!$C$3:$C$302=B9)*(Components!$F$3:$F$302=C9))),"No matches found")} -> CMF_1950_EXT_WALL_MEDIUM_SKIN | E9: CMF_1950_EXT_WALL_MEDIUM_STRUCTURE | F9: CMF_1950_EXT_WALL_MEDIUM_SPACE
A10: =C10&"_"&B10 -> CMF_1950_EXT_WALL_HIGH | B10: EXT_WALL_HIGH | C10: CMF_1950 | D10: {=IFERROR(TRANSPOSE(_xlfn._xlws.FILTER(Components!$A$3:$A$302,(Components!$C$3:$C$302=B10)*(Components!$F$3:$F$302=C10))),"No matches found")} -> CMF_1950_EXT_WALL_HIGH_SKIN | E10: CMF_1950_EXT_WALL_HIGH_STRUCTURE
A11: =C11&"_"&B11 -> CMF_1950_BASEMENT_WALL | B11: BASEMENT_WALL | C11: CMF_1950 | D11: {=IFERROR(TRANSPOSE(_xlfn._xlws.FILTER(Components!$A$3:$A$302,(Components!$C$3:$C$302=B11)*(Components!$F$3:$F$302=C11))),"No matches found")} -> CMF_1950_BASEMENT_WALL_SPACE | E11: CMF_1950_BASEMENT_WALL_STRUCTURE | F11: CMF_1950_BASEMENT_WALL_STRUCTURE
A12: =C12&"_"&B12 -> CMF_1950_INT_WALL_LOADBEARING | B12: INT_WALL_LOADBEARING | C12: CMF_1950 | D12: {=IFERROR(TRANSPOSE(_xlfn._xlws.FILTER(Components!$A$3:$A$302,(Components!$C$3:$C$302=B12)*(Components!$F$3:$F$302=C12))),"No matches found")} -> CMF_1950_INT_WALL_LOADBEARING_STRUCTURE
A13: =C13&"_"&B13 -> CMF_1950_INT_WALL_NONLOADBEARING | B13: INT_WALL_NONLOADBEARING | C13: CMF_1950 | D13: {=IFERROR(TRANSPOSE(_xlfn._xlws.FILTER(Components!$A$3:$A$302,(Components!$C$3:$C$302=B13)*(Components!$F$3:$F$302=C13))),"No matches found")} -> CMF_1950_INT_WALL_NONLOADBEARING_SKIN | E13: CMF_1950_INT_WALL_NONLOADBEARING_STRUCTURE | F13: CMF_1950_INT_WALL_NONLOADBEARING_SPACE | G13: CMF_1950_INT_WALL_NONLOADBEARING_STRUCTURE
A14: =C14&"_"&B14 -> CMF_1950_EXT_WALL | B14: EXT_WALL | C14: CMF_1950 | D14: {=IFERROR(TRANSPOSE(_xlfn._xlws.FILTER(Components!$A$3:$A$302,(Components!$C$3:$C$302=B14)*(Components!$F$3:$F$302=C14))),"No matches found")} -> No matches found
A15: =C15&"_"&B15 -> CMF_1940_1_ROOF | B15: ROOF | C15: CMF_1940_1 | D15: {=IFERROR(TRANSPOSE(_xlfn._xlws.FILTER(Components!$A$3:$A$302,(Components!$C$3:$C$302=B15)*(Components!$F$3:$F$302=C15))),"No matches found")} -> CMF_1940_1_ROOF_SKIN | E15: CMF_1940_1_ROOF_SKIN | F15: CMF_1940_1_ROOF_SKIN | G15: CMF_1940_1_ROOF_SKIN
A16: =C16&"_"&B16 -> CMF_1940_1_TOP_FLOOR | B16: TOP_FLOOR | C16: CMF_1940_1 | D16: {=IFERROR(TRANSPOSE(_xlfn._xlws.FILTER(Components!$A$3:$A$302,(Components!$C$3:$C$302=B16)*(Components!$F$3:$F$302=C16))),"No matches found")} -> CMF_1940_1_TOP_FLOOR_SPACE | E16: CMF_1940_1_TOP_FLOOR_SPACE | F16: CMF_1940_1_TOP_FLOOR_SPACE | G16: CMF_1940_1_TOP_FLOOR_STRUCTURE
A17: =C17&"_"&B17 -> CMF_1940_1_INTERMEDIATE_FLOOR | B17: INTERMEDIATE_FLOOR | C17: CMF_1940_1 | D17: {=IFERROR(TRANSPOSE(_xlfn._xlws.FILTER(Components!$A$3:$A$302,(Components!$C$3:$C$302=B17)*(Components!$F$3:$F$302=C17))),"No matches found")} -> CMF_1940_1_INTERMEDIATE_FLOOR_SPACE | E17: CMF_1940_1_INTERMEDIATE_FLOOR_SPACE | F17: CMF_1940_1_INTERMEDIATE_FLOOR_SPACE | G17: CMF_1940_1_INTERMEDIATE_FLOOR_STRUCTURE | H17: CMF_1940_1_INTERMEDIATE_FLOOR_SPACE | I17: CMF_1940_1_INTERMEDIATE_FLOOR_SPACE | J17: CMF_1940_1_INTERMEDIATE_FLOOR_SPACE
A18: =C18&"_"&B18 -> CMF_1940_1_GROUND_FLOOR | B18: GROUND_FLOOR | C18: CMF_1940_1 | D18: {=IFERROR(TRANSPOSE(_xlfn._xlws.FILTER(Components!$A$3:$A$302,(Components!$C$3:$C$302=B18)*(Components!$F$3:$F$302=C18))),"No matches found")} -> CMF_1940_1_GROUND_FLOOR_STRUCTURE | E18: CMF_1940_1_GROUND_FLOOR_SPACE | F18: CMF_1940_1_GROUND_FLOOR_SPACE | G18: CMF_1940_1_GROUND_FLOOR_SPACE
A19: =C19&"_"&B19 -> CMF_1940_1_BASEMENT_FLOOR | B19: BASEMENT_FLOOR | C19: CMF_1940_1 | D19: {=IFERROR(TRANSPOSE(_xlfn._xlws.FILTER(Components!$A$3:$A$302,(Components!$C$3:$C$302=B19)*(Components!$F$3:$F$302=C19))),"No matches found")} -> CMF_1940_1_BASEMENT_FLOOR_STRUCTURE
A20: =C20&"_"&B20 -> CMF_1940_1_EXT_WALL_LOW | B20: EXT_WALL_LOW | C20: CMF_1940_1 | D20: {=IFERROR(TRANSPOSE(_xlfn._xlws.FILTER(Components!$A$3:$A$302,(Components!$C$3:$C$302=B20)*(Components!$F$3:$F$302=C20))),"No matches found")} -> No matches found
A21: =C21&"_"&B21 -> CMF_1940_1_EXT_WALL_MEDIUM | B21: EXT_WALL_MEDIUM | C21: CMF_1940_1 | D21: {=IFERROR(TRANSPOSE(_xlfn._xlws.FILTER(Components!$A$3:$A$302,(Components!$C$3:$C$302=B21)*(Components!$F$3:$F$302=C21))),"No matches found")} -> No matches found
A22: =C22&"_"&B22 -> CMF_1940_1_EXT_WALL_HIGH | B22: EXT_WALL_HIGH | C22: CMF_1940_1 | D22: {=IFERROR(TRANSPOSE(_xlfn._xlws.FILTER(Components!$A$3:$A$302,(Components!$C$3:$C$302=B22)*(Components!$F$3:$F$302=C22))),"No matches found")} -> No matches found
A23: =C23&"_"&B23 -> CMF_1940_1_BASEMENT_WALL | B23: BASEMENT_WALL | C23: CMF_1940_1 | D23: {=IFERROR(TRANSPOSE(_xlfn._xlws.FILTER(Components!$A$3:$A$302,(Components!$C$3:$C$302=B23)*(Components!$F$3:$F$302=C23))),"No matches found")} -> CMF_1940_1_BASEMENT_WALL_SKIN | E23: CMF_1940_1_BASEMENT_WALL_STRUCTURE | F23: CMF_1940_1_BASEMENT_WALL_SPACE
A24: =C24&"_"&B24 -> CMF_1940_1_INT_WALL_LOADBEARING | B24: INT_WALL_LOADBEARING | C24: CMF_1940_1 | D24: {=IFERROR(TRANSPOSE(_xlfn._xlws.FILTER(Components!$A$3:$A$302,(Components!$C$3:$C$302=B24)*(Components!$F$3:$F$302=C24))),"No matches found")} -> CMF_1940_1_INT_WALL_LOADBEARING_SPACE | E24: CMF_1940_1_INT_WALL_LOADBEARING_STRUCTURE
A25: =C25&"_"&B25 -> CMF_1940_1_INT_WALL_NONLOADBEARING | B25: INT_WALL_NONLOADBEARING | C25: CMF_1940_1 | D25: {=IFERROR(TRANSPOSE(_xlfn._xlws.FILTER(Components!$A$3:$A$302,(Components!$C$3:$C$302=B25)*(Components!$F$3:$F$302=C25))),"No matches found")} -> CMF_1940_1_INT_WALL_NONLOADBEARING_SPACE | E25: CMF_1940_1_INT_WALL_NONLOADBEARING_SPACE
A26: =C26&"_"&B26 -> CMF_1940_1_EXT_WALL | B26: EXT_WALL | C26: CMF_1940_1 | D26: {=IFERROR(TRANSPOSE(_xlfn._xlws.FILTER(Components!$A$3:$A$302,(Components!$C$3:$C$302=B26)*(Components!$F$3:$F$302=C26))),"No matches found")} -> CMF_1940_1_EXT_WALL_SKIN | E26: CMF_1940_1_EXT_WALL_STRUCTURE | F26: CMF_1940_1_EXT_WALL_SPACE
A27: =C27&"_"&B27 -> CMF_1960_1_ROOF | B27: ROOF | C27: CMF_1960_1 | D27: {=IFERROR(TRANSPOSE(_xlfn._xlws.FILTER(Components!$A$3:$A$302,(Components!$C$3:$C$302=B27)*(Components!$F$3:$F$302=C27))),"No matches found")} -> CMF_1960_1_ROOF_SKIN | E27: CMF_1960_1_ROOF_SKIN | F27: CMF_1960_1_ROOF_SKIN | G27: CMF_1960_1_ROOF_SKIN | H27: CMF_1960_1_ROOF_SKIN
A28: =C28&"_"&B28 -> CMF_1960_1_TOP_FLOOR | B28: TOP_FLOOR | C28: CMF_1960_1 | D28: {=IFERROR(TRANSPOSE(_xlfn._xlws.FILTER(Components!$A$3:$A$302,(Components!$C$3:$C$302=B28)*(Components!$F$3:$F$302=C28))),"No matches found")} -> CMF_1960_1_TOP_FLOOR_SPACE | E28: CMF_1960_1_TOP_FLOOR_SPACE | F28: CMF_1960_1_TOP_FLOOR_SPACE | G28: CMF_1960_1_TOP_FLOOR_STRUCTURE
A29: =C29&"_"&B29 -> CMF_1960_1_INTERMEDIATE_FLOOR | B29: INTERMEDIATE_FLOOR | C29: CMF_1960_1 | D29: {=IFERROR(TRANSPOSE(_xlfn._xlws.FILTER(Components!$A$3:$A$302,(Components!$C$3:$C$302=B29)*(Components!$F$3:$F$302=C29))),"No matches found")} -> CMF_1960_1_INTERMEDIATE_FLOOR_SPACE | E29: CMF_1960_1_INTERMEDIATE_FLOOR_SPACE | F29: CMF_1960_1_INTERMEDIATE_FLOOR_STRUCTURE | G29: CMF_1960_1_INTERMEDIATE_FLOOR_SPACE
A30: =C30&"_"&B30 -> CMF_1960_1_GROUND_FLOOR | B30: GROUND_FLOOR | C30: CMF_1960_1 | D30: {=IFERROR(TRANSPOSE(_xlfn._xlws.FILTER(Components!$A$3:$A$302,(Components!$C$3:$C$302=B30)*(Components!$F$3:$F$302=C30))),"No matches found")} -> CMF_1960_1_GROUND_FLOOR_SPACE | E30: CMF_1960_1_GROUND_FLOOR_SPACE | F30: CMF_1960_1_GROUND_FLOOR_STRUCTURE | G30: CMF_1960_1_GROUND_FLOOR_SKIN
A31: =C31&"_"&B31 -> CMF_1960_1_BASEMENT_FLOOR | B31: BASEMENT_FLOOR | C31: CMF_1960_1 | D31: {=IFERROR(TRANSPOSE(_xlfn._xlws.FILTER(Components!$A$3:$A$302,(Components!$C$3:$C$302=B31)*(Components!$F$3:$F$302=C31))),"No matches found")} -> CMF_1960_1_BASEMENT_FLOOR_SKIN | E31: CMF_1960_1_BASEMENT_FLOOR_STRUCTURE | F31: CMF_1960_1_BASEMENT_FLOOR_SPACE
A32: =C32&"_"&B32 -> CMF_1960_1_EXT_WALL_LOW | B32: EXT_WALL_LOW | C32: CMF_1960_1 | D32: {=IFERROR(TRANSPOSE(_xlfn._xlws.FILTER(Components!$A$3:$A$302,(Components!$C$3:$C$302=B32)*(Components!$F$3:$F$302=C32))),"No matches found")} -> No matches found
A33: =C33&"_"&B33 -> CMF_1960_1_EXT_WALL_MEDIUM | B33: EXT_WALL_MEDIUM | C33: CMF_1960_1 | D33: {=IFERROR(TRANSPOSE(_xlfn._xlws.FILTER(Components!$A$3:$A$302,(Components!$C$3:$C$302=B33)*(Components!$F$3:$F$302=C33))),"No matches found")} -> No matches found
A34: =C34&"_"&B34 -> CMF_1960_1_EXT_WALL_HIGH | B34: EXT_WALL_HIGH | C34: CMF_1960_1 | D34: {=IFERROR(TRANSPOSE(_xlfn._xlws.FILTER(Components!$A$3:$A$302,(Components!$C$3:$C$302=B34)*(Components!$F$3:$F$302=C34))),"No matches found")} -> No matches found
A35: =C35&"_"&B35 -> CMF_1960_1_BASEMENT_WALL | B35: BASEMENT_WALL | C35: CMF_1960_1 | D35: {=IFERROR(TRANSPOSE(_xlfn._xlws.FILTER(Components!$A$3:$A$302,(Components!$C$3:$C$302=B35)*(Components!$F$3:$F$302=C35))),"No matches found")} -> CMF_1960_1_BASEMENT_WALL_SKIN | E35: CMF_1960_1_BASEMENT_WALL_STRUCTURE | F35: CMF_1960_1_BASEMENT_WALL_SPACE
A36: =C36&"_"&B36 -> CMF_1960_1_INT_WALL_LOADBEARING | B36: INT_WALL_LOADBEARING | C36: CMF_1960_1 | D36: {=IFERROR(TRANSPOSE(_xlfn._xlws.FILTER(Components!$A$3:$A$302,(Components!$C$3:$C$302=B36)*(Components!$F$3:$F$302=C36))),"No matches found")} -> CMF_1960_1_INT_WALL_LOADBEARING_SPACE | E36: CMF_1960_1_INT_WALL_LOADBEARING_STRUCTURE
A37: =C37&"_"&B37 -> CMF_1960_1_INT_WALL_NONLOADBEARING | B37: INT_WALL_NONLOADBEARING | C37: CMF_1960_1 | D37: {=IFERROR(TRANSPOSE(_xlfn._xlws.FILTER(Components!$A$3:$A$302,(Components!$C$3:$C$302=B37)*(Components!$F$3:$F$302=C37))),"No matches found")} -> CMF_1960_1_INT_WALL_NONLOADBEARING_SPACE | E37: CMF_1960_1_INT_WALL_NONLOADBEARING_STRUCTURE
A38: =C38&"_"&B38 -> CMF_1960_1_EXT_WALL | B38: EXT_WALL | C38: CMF_1960_1 | D38: {=IFERROR(TRANSPOSE(_xlfn._xlws.FILTER(Components!$A$3:$A$302,(Components!$C$3:$C$302=B38)*(Components!$F$3:$F$302=C38))),"No matches found")} -> CMF_1960_1_EXT_WALL_SKIN | E38: CMF_1960_1_EXT_WALL_SPACE | F38: CMF_1960_1_EXT_WALL_SKIN | G38: CMF_1960_1_EXT_WALL_STRUCTURE | H38: CMF_1960_1_EXT_WALL_SPACE | I38: CMF_1960_1_EXT_WALL_SPACE
A39: =C39&"_"&B39 -> CMF_1960_2_ROOF | B39: ROOF | C39: CMF_1960_2 | D39: {=IFERROR(TRANSPOSE(_xlfn._xlws.FILTER(Components!$A$3:$A$302,(Components!$C$3:$C$302=B39)*(Components!$F$3:$F$302=C39))),"No matches found")} -> CMF_1960_2_ROOF_SKIN | E39: CMF_1960_2_ROOF_SKIN | F39: CMF_1960_2_ROOF_SKIN | G39: CMF_1960_2_ROOF_STRUCTURE
A40: =C40&"_"&B40 -> CMF_1960_2_TOP_FLOOR | B40: TOP_FLOOR | C40: CMF_1960_2 | D40: {=IFERROR(TRANSPOSE(_xlfn._xlws.FILTER(Components!$A$3:$A$302,(Components!$C$3:$C$302=B40)*(Components!$F$3:$F$302=C40))),"No matches found")} -> CMF_1960_2_TOP_FLOOR_SPACE | E40: CMF_1960_2_TOP_FLOOR_SPACE | F40: CMF_1960_2_TOP_FLOOR_STRUCTURE
...

Sheet Building
A1: Archetype Code | B1: Multiple Exterior Wall defenitions? | C1: Roof Element | D1: Top Floor Element | E1: Intermediate Floor Element | F1: Ground Floor Element | G1: Basement Floor Element | H1: Exterior Wall Element | I1: Exterior Wall Low Element | J1: Exterior Wall Medium Element | K1: Exterior Wall High Element | L1: Basement Wall Element | M1: Interior Wall Loadbearing Element | N1: Interior Wall Non Loadbearing Element
A2: Code for the the archteype | B2: Yes if the archetype should a have exterior wall defenitions based on no. floors | C2: The roof element that should be used for th archetype | D2: The top floor element that should be used for th archetype | E2: The intermediate floor element that should be used for th archetype | F2: The ground floor element that should be used for th archetype | G2: The basement floor element that should be used for th archetype | H2: The exterior wall element that should be used for the archetype | I2: The exterior wall element that should be used for the archetype | J2: The exterior wall element that should be used for the archetype | K2: The exterior wall element that should be used for the archetype | L2: The basement wall element that should be used for th archetype | M2: The interior wall loadbearing element that should be used for th archetype | N2: The interior wall non loadbearing element that should be used for th archetype
A3: CMF_1940_1 | B3: No | C3: {=IF( COUNTIFS(Elements!$A$3:$A$300,"*"&Building!A3&"*",Elements!$B$3:$B$300,"ROOF",Elements!$D$3:$D$300,"No matches found")>0, "No components assigned to this element", IFERROR( _xlfn._xlws.FILTER(Elements!$A$3:$A$300,(ISNUMBER(SEARCH(Building!A3,Elements!$A$3:$A$300)))*(Elements!$B$3:$B$300="ROOF")), "No match" ))} -> CMF_1940_1_ROOF | D3: {=IF( COUNTIFS(Elements!$A$3:$A$300,"*"&Building!A3&"*",Elements!$B$3:$B$300,"TOP_FLOOR",Elements!$D$3:$D$300,"No matches found")>0, "No components assigned to this element", IFERROR( _xlfn._xlws.FILTER(Elements!$A$3:$A$300,(ISNUMBER(SEARCH(Building!A3,Elements!$A$3:$A$300)))*(Elements!$B$3:$B$300="TOP_FLOOR")), "No match" ))} -> CMF_1940_1_TOP_FLOOR | E3: {=IF( COUNTIFS(Elements!$A$3:$A$300,"*"&Building!A3&"*",Elements!$B$3:$B$300,"INTERMEDIATE_FLOOR",Elements!$D$3:$D$300,"No matches found")>0, "No components assigned to this element", IFERROR( _xlfn._xlws.FILTER(Elements!$A$3:$A$300,(ISNUMBER(SEARCH(Building!A3,Elements!$A$3:$A$300)))*(Elements!$B$3:$B$300="INTERMEDIATE_FLOOR")), "No match" ))} -> CMF_1940_1_INTERMEDIATE_FLOOR | F3: {=IF( COUNTIFS(Elements!$A$3:$A$300,"*"&Building!A3&"*",Elements!$B$3:$B$300,"GROUND_FLOOR",Elements!$D$3:$D$300,"No matches found")>0, "No components assigned to this element", IFERROR( _xlfn._xlws.FILTER(Elements!$A$3:$A$300,(ISNUMBER(SEARCH(Building!A3,Elements!$A$3:$A$300)))*(Elements!$B$3:$B$300="GROUND_FLOOR")), "No match" ))} -> CMF_1940_1_GROUND_FLOOR | G3: {=IF( COUNTIFS(Elements!$A$3:$A$300,"*"&Building!A3&"*",Elements!$B$3:$B$300,"BASEMENT_FLOOR",Elements!$D$3:$D$300,"No matches found")>0, "No components assigned to this element", IFERROR( _xlfn._xlws.FILTER(Elements!$A$3:$A$300,(ISNUMBER(SEARCH(Building!A3,Elements!$A$3:$A$300)))*(Elements!$B$3:$B$300="BASEMENT_FLOOR")), "No match" ))} -> CMF_1940_1_BASEMENT_FLOOR | H3: {=_xlfn.LET( _xlpm.x, IF( COUNTIFS(Elements!$A$3:$A$300,"*"&Building!A3&"*",Elements!$B$3:$B$300,"EXT_WALL",Elements!$D$3:$D$300,"No matches found")>0, "No components assigned to this element", IFERROR( _xlfn._xlws.FILTER(Elements!$A$3:$A$300,(ISNUMBER(SEARCH(Building!A3,Elements!$A$3:$A$300)))*(Elements!$B$3:$B$300="EXT_WALL")), "No match" ) ), IF((_xlpm.x="No components assigned to this element")*(B3="Yes"),"Not required",_xlpm.x) )} -> CMF_1940_1_EXT_WALL | I3: {=_xlfn.LET( _xlpm.x, IF( COUNTIFS(Elements!$A$3:$A$300,"*"&Building!A3&"*",Elements!$B$3:$B$300,"EXT_WALL_LOW",Elements!$D$3:$D$300,"No matches found")>0, "No components assigned to this element", IFERROR( _xlfn._xlws.FILTER(Elements!$A$3:$A$300,(ISNUMBER(SEARCH(Building!A3,Elements!$A$3:$A$300)))*(Elements!$B$3:$B$300="EXT_WALL_LOW")), "No match" ) ), IF((_xlpm.x="No components assigned to this element")*(B3="No"),"Not required",_xlpm.x) )} -> Not required | J3: {=_xlfn.LET( _xlpm.x, IF( COUNTIFS(Elements!$A$3:$A$300,"*"&Building!A3&"*",Elements!$B$3:$B$300,"EXT_WALL_MEDIUM",Elements!$D$3:$D$300,"No matches found")>0, "No components assigned to this element", IFERROR( _xlfn._xlws.FILTER(Elements!$A$3:$A$300,(ISNUMBER(SEARCH(Building!A3,Elements!$A$3:$A$300)))*(Elements!$B$3:$B$300="EXT_WALL_MEDIUM")), "No match" ) ), IF((_xlpm.x="No components assigned to this element")*(B3="No"),"Not required",_xlpm.x))} -> Not required | K3: {=_xlfn.LET( _xlpm.x, IF( COUNTIFS(Elements!$A$3:$A$300,"*"&Building!A3&"*",Elements!$B$3:$B$300,"EXT_WALL_HIGH",Elements!$D$3:$D$300,"No matches found")>0, "No components assigned to this element", IFERROR( _xlfn._xlws.FILTER(Elements!$A$3:$A$300,(ISNUMBER(SEARCH(Building!A3,Elements!$A$3:$A$300)))*(Elements!$B$3:$B$300="EXT_WALL_HIGH")), "No match" ) ), IF((_xlpm.x="No components assigned to this element")*(B3="No"),"Not required",_xlpm.x))} -> Not required | L3: {=IF( COUNTIFS(Elements!$A$3:$A$300,"*"&Building!A3&"*",Elements!$B$3:$B$300,"BASEMENT_WALL",Elements!$D$3:$D$300,"No matches found")>0, "No components assigned to this element", IFERROR( _xlfn._xlws.FILTER(Elements!$A$3:$A$300,(ISNUMBER(SEARCH(Building!A3,Elements!$A$3:$A$300)))*(Elements!$B$3:$B$300="BASEMENT_WALL")), "No match" ))} -> CMF_1940_1_BASEMENT_WALL | M3: {=IF( COUNTIFS(Elements!$A$3:$A$300,"*"&Building!A3&"*",Elements!$B$3:$B$300,"INT_WALL_LOADBEARING",Elements!$D$3:$D$300,"No matches found")>0, "No components assigned to this element", IFERROR( _xlfn._xlws.FILTER(Elements!$A$3:$A$300,(ISNUMBER(SEARCH(Building!A3,Elements!$A$3:$A$300)))*(Elements!$B$3:$B$300="INT_WALL_LOADBEARING")), "No match" ))} -> CMF_1940_1_INT_WALL_LOADBEARING | N3: {=IF( COUNTIFS(Elements!$A$3:$A$300,"*"&Building!A3&"*",Elements!$B$3:$B$300,"INT_WALL_NONLOADBEARING",Elements!$D$3:$D$300,"No matches found")>0, "No components assigned to this element", IFERROR( _xlfn._xlws.FILTER(Elements!$A$3:$A$300,(ISNUMBER(SEARCH(Building!A3,Elements!$A$3:$A$300)))*(Elements!$B$3:$B$300="INT_WALL_NONLOADBEARING")), "No match" ))} -> CMF_1940_1_INT_WALL_NONLOADBEARING
A4: CMF_1950 | B4: Yes | C4: {=IF( COUNTIFS(Elements!$A$3:$A$300,"*"&Building!A4&"*",Elements!$B$3:$B$300,"ROOF",Elements!$D$3:$D$300,"No matches found")>0, "No components assigned to this element", IFERROR( _xlfn._xlws.FILTER(Elements!$A$3:$A$300,(ISNUMBER(SEARCH(Building!A4,Elements!$A$3:$A$300)))*(Elements!$B$3:$B$300="ROOF")), "No match" ))} -> CMF_1950_ROOF | D4: {=IF( COUNTIFS(Elements!$A$3:$A$300,"*"&Building!A4&"*",Elements!$B$3:$B$300,"TOP_FLOOR",Elements!$D$3:$D$300,"No matches found")>0, "No components assigned to this element", IFERROR( _xlfn._xlws.FILTER(Elements!$A$3:$A$300,(ISNUMBER(SEARCH(Building!A4,Elements!$A$3:$A$300)))*(Elements!$B$3:$B$300="TOP_FLOOR")), "No match" ))} -> CMF_1950_TOP_FLOOR | E4: {=IF( COUNTIFS(Elements!$A$3:$A$300,"*"&Building!A4&"*",Elements!$B$3:$B$300,"INTERMEDIATE_FLOOR",Elements!$D$3:$D$300,"No matches found")>0, "No components assigned to this element", IFERROR( _xlfn._xlws.FILTER(Elements!$A$3:$A$300,(ISNUMBER(SEARCH(Building!A4,Elements!$A$3:$A$300)))*(Elements!$B$3:$B$300="INTERMEDIATE_FLOOR")), "No match" ))} -> CMF_1950_INTERMEDIATE_FLOOR | F4: {=IF( COUNTIFS(Elements!$A$3:$A$300,"*"&Building!A4&"*",Elements!$B$3:$B$300,"GROUND_FLOOR",Elements!$D$3:$D$300,"No matches found")>0, "No components assigned to this element", IFERROR( _xlfn._xlws.FILTER(Elements!$A$3:$A$300,(ISNUMBER(SEARCH(Building!A4,Elements!$A$3:$A$300)))*(Elements!$B$3:$B$300="GROUND_FLOOR")), "No match" ))} -> CMF_1950_GROUND_FLOOR | G4: {=IF( COUNTIFS(Elements!$A$3:$A$300,"*"&Building!A4&"*",Elements!$B$3:$B$300,"BASEMENT_FLOOR",Elements!$D$3:$D$300,"No matches found")>0, "No components assigned to this element", IFERROR( _xlfn._xlws.FILTER(Elements!$A$3:$A$300,(ISNUMBER(SEARCH(Building!A4,Elements!$A$3:$A$300)))*(Elements!$B$3:$B$300="BASEMENT_FLOOR")), "No match" ))} -> CMF_1950_BASEMENT_FLOOR | H4: {=_xlfn.LET( _xlpm.x, IF( COUNTIFS(Elements!$A$3:$A$300,"*"&Building!A4&"*",Elements!$B$3:$B$300,"EXT_WALL",Elements!$D$3:$D$300,"No matches found")>0, "No components assigned to this element", IFERROR( _xlfn._xlws.FILTER(Elements!$A$3:$A$300,(ISNUMBER(SEARCH(Building!A4,Elements!$A$3:$A$300)))*(Elements!$B$3:$B$300="EXT_WALL")), "No match" ) ), IF((_xlpm.x="No components assigned to this element")*(B4="Yes"),"Not required",_xlpm.x) )} -> Not required | I4: {=_xlfn.LET( _xlpm.x, IF( COUNTIFS(Elements!$A$3:$A$300,"*"&Building!A4&"*",Elements!$B$3:$B$300,"EXT_WALL_LOW",Elements!$D$3:$D$300,"No matches found")>0, "No components assigned to this element", IFERROR( _xlfn._xlws.FILTER(Elements!$A$3:$A$300,(ISNUMBER(SEARCH(Building!A4,Elements!$A$3:$A$300)))*(Elements!$B$3:$B$300="EXT_WALL_LOW")), "No match" ) ), IF((_xlpm.x="No components assigned to this element")*(B4="No"),"Not required",_xlpm.x) )} -> CMF_1950_EXT_WALL_LOW | J4: {=_xlfn.LET( _xlpm.x, IF( COUNTIFS(Elements!$A$3:$A$300,"*"&Building!A4&"*",Elements!$B$3:$B$300,"EXT_WALL_MEDIUM",Elements!$D$3:$D$300,"No matches found")>0, "No components assigned to this element", IFERROR( _xlfn._xlws.FILTER(Elements!$A$3:$A$300,(ISNUMBER(SEARCH(Building!A4,Elements!$A$3:$A$300)))*(Elements!$B$3:$B$300="EXT_WALL_MEDIUM")), "No match" ) ), IF((_xlpm.x="No components assigned to this element")*(B4="No"),"Not required",_xlpm.x))} -> CMF_1950_EXT_WALL_MEDIUM | K4: {=_xlfn.LET( _xlpm.x, IF( COUNTIFS(Elements!$A$3:$A$300,"*"&Building!A4&"*",Elements!$B$3:$B$300,"EXT_WALL_HIGH",Elements!$D$3:$D$300,"No matches found")>0, "No components assigned to this element", IFERROR( _xlfn._xlws.FILTER(Elements!$A$3:$A$300,(ISNUMBER(SEARCH(Building!A4,Elements!$A$3:$A$300)))*(Elements!$B$3:$B$300="EXT_WALL_HIGH")), "No match" ) ), IF((_xlpm.x="No components assigned to this element")*(B4="No"),"Not required",_xlpm.x))} -> CMF_1950_EXT_WALL_HIGH | L4: {=IF( COUNTIFS(Elements!$A$3:$A$300,"*"&Building!A4&"*",Elements!$B$3:$B$300,"BASEMENT_WALL",Elements!$D$3:$D$300,"No matches found")>0, "No components assigned to this element", IFERROR( _xlfn._xlws.FILTER(Elements!$A$3:$A$300,(ISNUMBER(SEARCH(Building!A4,Elements!$A$3:$A$300)))*(Elements!$B$3:$B$300="BASEMENT_WALL")), "No match" ))} -> CMF_1950_BASEMENT_WALL | M4: {=IF( COUNTIFS(Elements!$A$3:$A$300,"*"&Building!A4&"*",Elements!$B$3:$B$300,"INT_WALL_LOADBEARING",Elements!$D$3:$D$300,"No matches found")>0, "No components assigned to this element", IFERROR( _xlfn._xlws.FILTER(Elements!$A$3:$A$300,(ISNUMBER(SEARCH(Building!A4,Elements!$A$3:$A$300)))*(Elements!$B$3:$B$300="INT_WALL_LOADBEARING")), "No match" ))} -> CMF_1950_INT_WALL_LOADBEARING | N4: {=IF( COUNTIFS(Elements!$A$3:$A$300,"*"&Building!A4&"*",Elements!$B$3:$B$300,"INT_WALL_NONLOADBEARING",Elements!$D$3:$D$300,"No matches found")>0, "No components assigned to this element", IFERROR( _xlfn._xlws.FILTER(Elements!$A$3:$A$300,(ISNUMBER(SEARCH(Building!A4,Elements!$A$3:$A$300)))*(Elements!$B$3:$B$300="INT_WALL_NONLOADBEARING")), "No match" ))} -> CMF_1950_INT_WALL_NONLOADBEARING
